{
 "cells": [
  {
   "cell_type": "code",
   "execution_count": 1,
   "metadata": {},
   "outputs": [],
   "source": [
    "# standard library\n",
    "from collections import namedtuple\n",
    "import io\n",
    "import os\n",
    "import numpy as np\n",
    "import pandas as pd\n",
    "\n",
    "# plot.ly modules\n",
    "import dash\n",
    "from dash.dependencies import Output, Event\n",
    "import dash_core_components as dcc\n",
    "import dash_html_components as html\n",
    "import plotly.graph_objs as go"
   ]
  },
  {
   "cell_type": "code",
   "execution_count": 22,
   "metadata": {},
   "outputs": [
    {
     "ename": "SyntaxError",
     "evalue": "invalid syntax (<ipython-input-22-6af34dc2b375>, line 5)",
     "output_type": "error",
     "traceback": [
      "\u001b[0;36m  File \u001b[0;32m\"<ipython-input-22-6af34dc2b375>\"\u001b[0;36m, line \u001b[0;32m5\u001b[0m\n\u001b[0;31m    def get_data(global rows):\u001b[0m\n\u001b[0m                      ^\u001b[0m\n\u001b[0;31mSyntaxError\u001b[0m\u001b[0;31m:\u001b[0m invalid syntax\n"
     ]
    }
   ],
   "source": [
    "df = pd.read_csv('combined_normalized.csv')\n",
    "col = ['speed','pm10','pm25','no2','co']\n",
    "global rows \n",
    "rows = len(df)\n",
    "def get_data(rows):\n",
    "    rows += 1\n",
    "    print(rows)"
   ]
  },
  {
   "cell_type": "code",
   "execution_count": 21,
   "metadata": {},
   "outputs": [
    {
     "name": "stdout",
     "output_type": "stream",
     "text": [
      "104\n"
     ]
    }
   ],
   "source": [
    "get_data(rows)"
   ]
  },
  {
   "cell_type": "code",
   "execution_count": 5,
   "metadata": {},
   "outputs": [
    {
     "data": {
      "text/html": [
       "<div>\n",
       "<style scoped>\n",
       "    .dataframe tbody tr th:only-of-type {\n",
       "        vertical-align: middle;\n",
       "    }\n",
       "\n",
       "    .dataframe tbody tr th {\n",
       "        vertical-align: top;\n",
       "    }\n",
       "\n",
       "    .dataframe thead th {\n",
       "        text-align: right;\n",
       "    }\n",
       "</style>\n",
       "<table border=\"1\" class=\"dataframe\">\n",
       "  <thead>\n",
       "    <tr style=\"text-align: right;\">\n",
       "      <th></th>\n",
       "      <th>new_date</th>\n",
       "      <th>lat</th>\n",
       "      <th>long</th>\n",
       "      <th>speed</th>\n",
       "      <th>datetime</th>\n",
       "      <th>co</th>\n",
       "      <th>no2</th>\n",
       "      <th>o3</th>\n",
       "      <th>pm10</th>\n",
       "      <th>pm25</th>\n",
       "      <th>so2</th>\n",
       "      <th>no2_normal</th>\n",
       "      <th>o3_normal</th>\n",
       "      <th>pm10_normal</th>\n",
       "      <th>pm25_normal</th>\n",
       "      <th>so2_normal</th>\n",
       "      <th>co_normal</th>\n",
       "    </tr>\n",
       "  </thead>\n",
       "  <tbody>\n",
       "    <tr>\n",
       "      <th>0</th>\n",
       "      <td>2018-07-01T05:00:00</td>\n",
       "      <td>40.70158</td>\n",
       "      <td>-73.990330</td>\n",
       "      <td>33.55</td>\n",
       "      <td>2018-07-01T05:00:00</td>\n",
       "      <td>412.11</td>\n",
       "      <td>66.61</td>\n",
       "      <td>26.70</td>\n",
       "      <td>79.33</td>\n",
       "      <td>20.09</td>\n",
       "      <td>0.07</td>\n",
       "      <td>0.030021</td>\n",
       "      <td>-3.846154</td>\n",
       "      <td>0.031309</td>\n",
       "      <td>0.112740</td>\n",
       "      <td>33.333333</td>\n",
       "      <td>0.008814</td>\n",
       "    </tr>\n",
       "    <tr>\n",
       "      <th>1</th>\n",
       "      <td>2018-07-02T06:00:00</td>\n",
       "      <td>40.66579</td>\n",
       "      <td>-73.757060</td>\n",
       "      <td>31.68</td>\n",
       "      <td>2018-07-02T06:00:00</td>\n",
       "      <td>414.54</td>\n",
       "      <td>39.52</td>\n",
       "      <td>14.46</td>\n",
       "      <td>63.54</td>\n",
       "      <td>29.13</td>\n",
       "      <td>0.83</td>\n",
       "      <td>0.132375</td>\n",
       "      <td>-0.149629</td>\n",
       "      <td>0.112642</td>\n",
       "      <td>0.459293</td>\n",
       "      <td>7.205360</td>\n",
       "      <td>0.016624</td>\n",
       "    </tr>\n",
       "    <tr>\n",
       "      <th>2</th>\n",
       "      <td>2018-07-02T06:00:00</td>\n",
       "      <td>40.70895</td>\n",
       "      <td>-73.996941</td>\n",
       "      <td>32.93</td>\n",
       "      <td>2018-07-02T06:00:00</td>\n",
       "      <td>455.08</td>\n",
       "      <td>44.86</td>\n",
       "      <td>21.06</td>\n",
       "      <td>50.80</td>\n",
       "      <td>26.16</td>\n",
       "      <td>1.27</td>\n",
       "      <td>0.074749</td>\n",
       "      <td>-0.086980</td>\n",
       "      <td>0.021953</td>\n",
       "      <td>0.072515</td>\n",
       "      <td>1.655860</td>\n",
       "      <td>0.007551</td>\n",
       "    </tr>\n",
       "    <tr>\n",
       "      <th>3</th>\n",
       "      <td>2018-07-02T06:00:00</td>\n",
       "      <td>40.76212</td>\n",
       "      <td>-74.910000</td>\n",
       "      <td>18.64</td>\n",
       "      <td>2018-07-02T06:00:00</td>\n",
       "      <td>333.47</td>\n",
       "      <td>8.91</td>\n",
       "      <td>24.92</td>\n",
       "      <td>17.26</td>\n",
       "      <td>16.20</td>\n",
       "      <td>0.02</td>\n",
       "      <td>0.278626</td>\n",
       "      <td>-0.071400</td>\n",
       "      <td>0.011558</td>\n",
       "      <td>0.564809</td>\n",
       "      <td>-36.251403</td>\n",
       "      <td>0.013018</td>\n",
       "    </tr>\n",
       "    <tr>\n",
       "      <th>4</th>\n",
       "      <td>2018-07-02T06:00:00</td>\n",
       "      <td>40.74137</td>\n",
       "      <td>-74.008930</td>\n",
       "      <td>15.53</td>\n",
       "      <td>2018-07-02T06:00:00</td>\n",
       "      <td>455.69</td>\n",
       "      <td>44.17</td>\n",
       "      <td>21.29</td>\n",
       "      <td>50.39</td>\n",
       "      <td>26.33</td>\n",
       "      <td>1.44</td>\n",
       "      <td>0.253112</td>\n",
       "      <td>-0.070668</td>\n",
       "      <td>0.041340</td>\n",
       "      <td>0.311255</td>\n",
       "      <td>3.591401</td>\n",
       "      <td>0.016858</td>\n",
       "    </tr>\n",
       "  </tbody>\n",
       "</table>\n",
       "</div>"
      ],
      "text/plain": [
       "              new_date       lat       long  speed             datetime  \\\n",
       "0  2018-07-01T05:00:00  40.70158 -73.990330  33.55  2018-07-01T05:00:00   \n",
       "1  2018-07-02T06:00:00  40.66579 -73.757060  31.68  2018-07-02T06:00:00   \n",
       "2  2018-07-02T06:00:00  40.70895 -73.996941  32.93  2018-07-02T06:00:00   \n",
       "3  2018-07-02T06:00:00  40.76212 -74.910000  18.64  2018-07-02T06:00:00   \n",
       "4  2018-07-02T06:00:00  40.74137 -74.008930  15.53  2018-07-02T06:00:00   \n",
       "\n",
       "       co    no2     o3   pm10   pm25   so2  no2_normal  o3_normal  \\\n",
       "0  412.11  66.61  26.70  79.33  20.09  0.07    0.030021  -3.846154   \n",
       "1  414.54  39.52  14.46  63.54  29.13  0.83    0.132375  -0.149629   \n",
       "2  455.08  44.86  21.06  50.80  26.16  1.27    0.074749  -0.086980   \n",
       "3  333.47   8.91  24.92  17.26  16.20  0.02    0.278626  -0.071400   \n",
       "4  455.69  44.17  21.29  50.39  26.33  1.44    0.253112  -0.070668   \n",
       "\n",
       "   pm10_normal  pm25_normal  so2_normal  co_normal  \n",
       "0     0.031309     0.112740   33.333333   0.008814  \n",
       "1     0.112642     0.459293    7.205360   0.016624  \n",
       "2     0.021953     0.072515    1.655860   0.007551  \n",
       "3     0.011558     0.564809  -36.251403   0.013018  \n",
       "4     0.041340     0.311255    3.591401   0.016858  "
      ]
     },
     "execution_count": 5,
     "metadata": {},
     "output_type": "execute_result"
    }
   ],
   "source": []
  },
  {
   "cell_type": "code",
   "execution_count": 27,
   "metadata": {},
   "outputs": [],
   "source": [
    "app = dash.Dash()\n",
    "\n",
    "app.layout = html.Div([\n",
    "    dcc.Graph(\n",
    "        id='live-graph', \n",
    "    ),\n",
    "    dcc.Interval(\n",
    "        id='interval-component',\n",
    "        interval=1*1000  # in milliseconds\n",
    "    )\n",
    "])\n",
    "\n",
    "\n",
    "@app.callback(Output('live-graph', 'figure'),\n",
    "              events=[Event('interval-component', 'interval')])\n",
    "def update_graph():\n",
    "#    result = get_data('data/data.csv', nlines=200)\n",
    "    df = pd.read_csv('data/data.csv')\n",
    "    x = df.iloc[np.random.randint(0,len(df))]\n",
    "    return {\n",
    "        'data': [\n",
    "            go.Scatter(\n",
    "                x=result.speed,\n",
    "                y=result.pm25\n",
    "            )\n",
    "        ]\n",
    "    }\n"
   ]
  },
  {
   "cell_type": "code",
   "execution_count": 28,
   "metadata": {},
   "outputs": [
    {
     "name": "stderr",
     "output_type": "stream",
     "text": [
      " * Running on http://0.0.0.0:8050/ (Press CTRL+C to quit)\n",
      "127.0.0.1 - - [22/Jul/2018 00:02:11] \"GET / HTTP/1.1\" 200 -\n",
      "127.0.0.1 - - [22/Jul/2018 00:02:12] \"GET /_dash-layout HTTP/1.1\" 200 -\n",
      "127.0.0.1 - - [22/Jul/2018 00:02:12] \"GET /_dash-dependencies HTTP/1.1\" 200 -\n",
      "127.0.0.1 - - [22/Jul/2018 00:02:12] \"GET /favicon.ico HTTP/1.1\" 200 -\n",
      "[2018-07-22 00:02:13,598] ERROR in app: Exception on /_dash-update-component [POST]\n",
      "Traceback (most recent call last):\n",
      "  File \"/home/abdulliaqat/anaconda3/lib/python3.6/site-packages/flask/app.py\", line 1982, in wsgi_app\n",
      "    response = self.full_dispatch_request()\n",
      "  File \"/home/abdulliaqat/anaconda3/lib/python3.6/site-packages/flask/app.py\", line 1614, in full_dispatch_request\n",
      "    rv = self.handle_user_exception(e)\n",
      "  File \"/home/abdulliaqat/anaconda3/lib/python3.6/site-packages/flask/app.py\", line 1517, in handle_user_exception\n",
      "    reraise(exc_type, exc_value, tb)\n",
      "  File \"/home/abdulliaqat/anaconda3/lib/python3.6/site-packages/flask/_compat.py\", line 33, in reraise\n",
      "    raise value\n",
      "  File \"/home/abdulliaqat/anaconda3/lib/python3.6/site-packages/flask/app.py\", line 1612, in full_dispatch_request\n",
      "    rv = self.dispatch_request()\n",
      "  File \"/home/abdulliaqat/anaconda3/lib/python3.6/site-packages/flask/app.py\", line 1598, in dispatch_request\n",
      "    return self.view_functions[rule.endpoint](**req.view_args)\n",
      "  File \"/home/abdulliaqat/anaconda3/lib/python3.6/site-packages/dash/dash.py\", line 558, in dispatch\n",
      "    return self.callback_map[target_id]['callback'](*args)\n",
      "  File \"/home/abdulliaqat/anaconda3/lib/python3.6/site-packages/dash/dash.py\", line 515, in add_context\n",
      "    output_value = func(*args, **kwargs)\n",
      "  File \"<ipython-input-27-c839ba81d55e>\", line 23, in update_graph\n",
      "    x=result.speed,\n",
      "NameError: name 'result' is not defined\n",
      "127.0.0.1 - - [22/Jul/2018 00:02:13] \"POST /_dash-update-component HTTP/1.1\" 500 -\n",
      "[2018-07-22 00:02:14,589] ERROR in app: Exception on /_dash-update-component [POST]\n",
      "Traceback (most recent call last):\n",
      "  File \"/home/abdulliaqat/anaconda3/lib/python3.6/site-packages/flask/app.py\", line 1982, in wsgi_app\n",
      "    response = self.full_dispatch_request()\n",
      "  File \"/home/abdulliaqat/anaconda3/lib/python3.6/site-packages/flask/app.py\", line 1614, in full_dispatch_request\n",
      "    rv = self.handle_user_exception(e)\n",
      "  File \"/home/abdulliaqat/anaconda3/lib/python3.6/site-packages/flask/app.py\", line 1517, in handle_user_exception\n",
      "    reraise(exc_type, exc_value, tb)\n",
      "  File \"/home/abdulliaqat/anaconda3/lib/python3.6/site-packages/flask/_compat.py\", line 33, in reraise\n",
      "    raise value\n",
      "  File \"/home/abdulliaqat/anaconda3/lib/python3.6/site-packages/flask/app.py\", line 1612, in full_dispatch_request\n",
      "    rv = self.dispatch_request()\n",
      "  File \"/home/abdulliaqat/anaconda3/lib/python3.6/site-packages/flask/app.py\", line 1598, in dispatch_request\n",
      "    return self.view_functions[rule.endpoint](**req.view_args)\n",
      "  File \"/home/abdulliaqat/anaconda3/lib/python3.6/site-packages/dash/dash.py\", line 558, in dispatch\n",
      "    return self.callback_map[target_id]['callback'](*args)\n",
      "  File \"/home/abdulliaqat/anaconda3/lib/python3.6/site-packages/dash/dash.py\", line 515, in add_context\n",
      "    output_value = func(*args, **kwargs)\n",
      "  File \"<ipython-input-27-c839ba81d55e>\", line 23, in update_graph\n",
      "    x=result.speed,\n",
      "NameError: name 'result' is not defined\n",
      "127.0.0.1 - - [22/Jul/2018 00:02:14] \"POST /_dash-update-component HTTP/1.1\" 500 -\n",
      "[2018-07-22 00:02:15,589] ERROR in app: Exception on /_dash-update-component [POST]\n",
      "Traceback (most recent call last):\n",
      "  File \"/home/abdulliaqat/anaconda3/lib/python3.6/site-packages/flask/app.py\", line 1982, in wsgi_app\n",
      "    response = self.full_dispatch_request()\n",
      "  File \"/home/abdulliaqat/anaconda3/lib/python3.6/site-packages/flask/app.py\", line 1614, in full_dispatch_request\n",
      "    rv = self.handle_user_exception(e)\n",
      "  File \"/home/abdulliaqat/anaconda3/lib/python3.6/site-packages/flask/app.py\", line 1517, in handle_user_exception\n",
      "    reraise(exc_type, exc_value, tb)\n",
      "  File \"/home/abdulliaqat/anaconda3/lib/python3.6/site-packages/flask/_compat.py\", line 33, in reraise\n",
      "    raise value\n",
      "  File \"/home/abdulliaqat/anaconda3/lib/python3.6/site-packages/flask/app.py\", line 1612, in full_dispatch_request\n",
      "    rv = self.dispatch_request()\n",
      "  File \"/home/abdulliaqat/anaconda3/lib/python3.6/site-packages/flask/app.py\", line 1598, in dispatch_request\n",
      "    return self.view_functions[rule.endpoint](**req.view_args)\n",
      "  File \"/home/abdulliaqat/anaconda3/lib/python3.6/site-packages/dash/dash.py\", line 558, in dispatch\n",
      "    return self.callback_map[target_id]['callback'](*args)\n",
      "  File \"/home/abdulliaqat/anaconda3/lib/python3.6/site-packages/dash/dash.py\", line 515, in add_context\n",
      "    output_value = func(*args, **kwargs)\n",
      "  File \"<ipython-input-27-c839ba81d55e>\", line 23, in update_graph\n",
      "    x=result.speed,\n",
      "NameError: name 'result' is not defined\n",
      "127.0.0.1 - - [22/Jul/2018 00:02:15] \"POST /_dash-update-component HTTP/1.1\" 500 -\n",
      "[2018-07-22 00:02:16,923] ERROR in app: Exception on /_dash-update-component [POST]\n",
      "Traceback (most recent call last):\n",
      "  File \"/home/abdulliaqat/anaconda3/lib/python3.6/site-packages/flask/app.py\", line 1982, in wsgi_app\n",
      "    response = self.full_dispatch_request()\n",
      "  File \"/home/abdulliaqat/anaconda3/lib/python3.6/site-packages/flask/app.py\", line 1614, in full_dispatch_request\n",
      "    rv = self.handle_user_exception(e)\n",
      "  File \"/home/abdulliaqat/anaconda3/lib/python3.6/site-packages/flask/app.py\", line 1517, in handle_user_exception\n",
      "    reraise(exc_type, exc_value, tb)\n",
      "  File \"/home/abdulliaqat/anaconda3/lib/python3.6/site-packages/flask/_compat.py\", line 33, in reraise\n",
      "    raise value\n",
      "  File \"/home/abdulliaqat/anaconda3/lib/python3.6/site-packages/flask/app.py\", line 1612, in full_dispatch_request\n",
      "    rv = self.dispatch_request()\n",
      "  File \"/home/abdulliaqat/anaconda3/lib/python3.6/site-packages/flask/app.py\", line 1598, in dispatch_request\n",
      "    return self.view_functions[rule.endpoint](**req.view_args)\n",
      "  File \"/home/abdulliaqat/anaconda3/lib/python3.6/site-packages/dash/dash.py\", line 558, in dispatch\n",
      "    return self.callback_map[target_id]['callback'](*args)\n",
      "  File \"/home/abdulliaqat/anaconda3/lib/python3.6/site-packages/dash/dash.py\", line 515, in add_context\n",
      "    output_value = func(*args, **kwargs)\n",
      "  File \"<ipython-input-27-c839ba81d55e>\", line 23, in update_graph\n",
      "    x=result.speed,\n",
      "NameError: name 'result' is not defined\n",
      "127.0.0.1 - - [22/Jul/2018 00:02:16] \"POST /_dash-update-component HTTP/1.1\" 500 -\n",
      "[2018-07-22 00:02:17,980] ERROR in app: Exception on /_dash-update-component [POST]\n",
      "Traceback (most recent call last):\n",
      "  File \"/home/abdulliaqat/anaconda3/lib/python3.6/site-packages/flask/app.py\", line 1982, in wsgi_app\n",
      "    response = self.full_dispatch_request()\n",
      "  File \"/home/abdulliaqat/anaconda3/lib/python3.6/site-packages/flask/app.py\", line 1614, in full_dispatch_request\n",
      "    rv = self.handle_user_exception(e)\n",
      "  File \"/home/abdulliaqat/anaconda3/lib/python3.6/site-packages/flask/app.py\", line 1517, in handle_user_exception\n",
      "    reraise(exc_type, exc_value, tb)\n",
      "  File \"/home/abdulliaqat/anaconda3/lib/python3.6/site-packages/flask/_compat.py\", line 33, in reraise\n",
      "    raise value\n",
      "  File \"/home/abdulliaqat/anaconda3/lib/python3.6/site-packages/flask/app.py\", line 1612, in full_dispatch_request\n",
      "    rv = self.dispatch_request()\n",
      "  File \"/home/abdulliaqat/anaconda3/lib/python3.6/site-packages/flask/app.py\", line 1598, in dispatch_request\n",
      "    return self.view_functions[rule.endpoint](**req.view_args)\n",
      "  File \"/home/abdulliaqat/anaconda3/lib/python3.6/site-packages/dash/dash.py\", line 558, in dispatch\n",
      "    return self.callback_map[target_id]['callback'](*args)\n",
      "  File \"/home/abdulliaqat/anaconda3/lib/python3.6/site-packages/dash/dash.py\", line 515, in add_context\n",
      "    output_value = func(*args, **kwargs)\n",
      "  File \"<ipython-input-27-c839ba81d55e>\", line 23, in update_graph\n",
      "    x=result.speed,\n",
      "NameError: name 'result' is not defined\n",
      "127.0.0.1 - - [22/Jul/2018 00:02:17] \"POST /_dash-update-component HTTP/1.1\" 500 -\n",
      "[2018-07-22 00:02:18,943] ERROR in app: Exception on /_dash-update-component [POST]\n",
      "Traceback (most recent call last):\n",
      "  File \"/home/abdulliaqat/anaconda3/lib/python3.6/site-packages/flask/app.py\", line 1982, in wsgi_app\n",
      "    response = self.full_dispatch_request()\n",
      "  File \"/home/abdulliaqat/anaconda3/lib/python3.6/site-packages/flask/app.py\", line 1614, in full_dispatch_request\n",
      "    rv = self.handle_user_exception(e)\n",
      "  File \"/home/abdulliaqat/anaconda3/lib/python3.6/site-packages/flask/app.py\", line 1517, in handle_user_exception\n",
      "    reraise(exc_type, exc_value, tb)\n",
      "  File \"/home/abdulliaqat/anaconda3/lib/python3.6/site-packages/flask/_compat.py\", line 33, in reraise\n",
      "    raise value\n",
      "  File \"/home/abdulliaqat/anaconda3/lib/python3.6/site-packages/flask/app.py\", line 1612, in full_dispatch_request\n",
      "    rv = self.dispatch_request()\n",
      "  File \"/home/abdulliaqat/anaconda3/lib/python3.6/site-packages/flask/app.py\", line 1598, in dispatch_request\n",
      "    return self.view_functions[rule.endpoint](**req.view_args)\n",
      "  File \"/home/abdulliaqat/anaconda3/lib/python3.6/site-packages/dash/dash.py\", line 558, in dispatch\n",
      "    return self.callback_map[target_id]['callback'](*args)\n",
      "  File \"/home/abdulliaqat/anaconda3/lib/python3.6/site-packages/dash/dash.py\", line 515, in add_context\n",
      "    output_value = func(*args, **kwargs)\n",
      "  File \"<ipython-input-27-c839ba81d55e>\", line 23, in update_graph\n",
      "    x=result.speed,\n",
      "NameError: name 'result' is not defined\n",
      "127.0.0.1 - - [22/Jul/2018 00:02:18] \"POST /_dash-update-component HTTP/1.1\" 500 -\n",
      "[2018-07-22 00:02:19,921] ERROR in app: Exception on /_dash-update-component [POST]\n",
      "Traceback (most recent call last):\n",
      "  File \"/home/abdulliaqat/anaconda3/lib/python3.6/site-packages/flask/app.py\", line 1982, in wsgi_app\n",
      "    response = self.full_dispatch_request()\n",
      "  File \"/home/abdulliaqat/anaconda3/lib/python3.6/site-packages/flask/app.py\", line 1614, in full_dispatch_request\n",
      "    rv = self.handle_user_exception(e)\n",
      "  File \"/home/abdulliaqat/anaconda3/lib/python3.6/site-packages/flask/app.py\", line 1517, in handle_user_exception\n",
      "    reraise(exc_type, exc_value, tb)\n",
      "  File \"/home/abdulliaqat/anaconda3/lib/python3.6/site-packages/flask/_compat.py\", line 33, in reraise\n",
      "    raise value\n",
      "  File \"/home/abdulliaqat/anaconda3/lib/python3.6/site-packages/flask/app.py\", line 1612, in full_dispatch_request\n",
      "    rv = self.dispatch_request()\n",
      "  File \"/home/abdulliaqat/anaconda3/lib/python3.6/site-packages/flask/app.py\", line 1598, in dispatch_request\n",
      "    return self.view_functions[rule.endpoint](**req.view_args)\n",
      "  File \"/home/abdulliaqat/anaconda3/lib/python3.6/site-packages/dash/dash.py\", line 558, in dispatch\n",
      "    return self.callback_map[target_id]['callback'](*args)\n",
      "  File \"/home/abdulliaqat/anaconda3/lib/python3.6/site-packages/dash/dash.py\", line 515, in add_context\n",
      "    output_value = func(*args, **kwargs)\n",
      "  File \"<ipython-input-27-c839ba81d55e>\", line 23, in update_graph\n",
      "    x=result.speed,\n",
      "NameError: name 'result' is not defined\n",
      "127.0.0.1 - - [22/Jul/2018 00:02:19] \"POST /_dash-update-component HTTP/1.1\" 500 -\n",
      "[2018-07-22 00:02:20,951] ERROR in app: Exception on /_dash-update-component [POST]\n",
      "Traceback (most recent call last):\n",
      "  File \"/home/abdulliaqat/anaconda3/lib/python3.6/site-packages/flask/app.py\", line 1982, in wsgi_app\n",
      "    response = self.full_dispatch_request()\n",
      "  File \"/home/abdulliaqat/anaconda3/lib/python3.6/site-packages/flask/app.py\", line 1614, in full_dispatch_request\n",
      "    rv = self.handle_user_exception(e)\n",
      "  File \"/home/abdulliaqat/anaconda3/lib/python3.6/site-packages/flask/app.py\", line 1517, in handle_user_exception\n",
      "    reraise(exc_type, exc_value, tb)\n",
      "  File \"/home/abdulliaqat/anaconda3/lib/python3.6/site-packages/flask/_compat.py\", line 33, in reraise\n",
      "    raise value\n",
      "  File \"/home/abdulliaqat/anaconda3/lib/python3.6/site-packages/flask/app.py\", line 1612, in full_dispatch_request\n",
      "    rv = self.dispatch_request()\n",
      "  File \"/home/abdulliaqat/anaconda3/lib/python3.6/site-packages/flask/app.py\", line 1598, in dispatch_request\n",
      "    return self.view_functions[rule.endpoint](**req.view_args)\n",
      "  File \"/home/abdulliaqat/anaconda3/lib/python3.6/site-packages/dash/dash.py\", line 558, in dispatch\n",
      "    return self.callback_map[target_id]['callback'](*args)\n",
      "  File \"/home/abdulliaqat/anaconda3/lib/python3.6/site-packages/dash/dash.py\", line 515, in add_context\n",
      "    output_value = func(*args, **kwargs)\n",
      "  File \"<ipython-input-27-c839ba81d55e>\", line 23, in update_graph\n",
      "    x=result.speed,\n",
      "NameError: name 'result' is not defined\n",
      "127.0.0.1 - - [22/Jul/2018 00:02:20] \"POST /_dash-update-component HTTP/1.1\" 500 -\n",
      "[2018-07-22 00:02:21,954] ERROR in app: Exception on /_dash-update-component [POST]\n",
      "Traceback (most recent call last):\n",
      "  File \"/home/abdulliaqat/anaconda3/lib/python3.6/site-packages/flask/app.py\", line 1982, in wsgi_app\n",
      "    response = self.full_dispatch_request()\n",
      "  File \"/home/abdulliaqat/anaconda3/lib/python3.6/site-packages/flask/app.py\", line 1614, in full_dispatch_request\n",
      "    rv = self.handle_user_exception(e)\n",
      "  File \"/home/abdulliaqat/anaconda3/lib/python3.6/site-packages/flask/app.py\", line 1517, in handle_user_exception\n",
      "    reraise(exc_type, exc_value, tb)\n",
      "  File \"/home/abdulliaqat/anaconda3/lib/python3.6/site-packages/flask/_compat.py\", line 33, in reraise\n",
      "    raise value\n",
      "  File \"/home/abdulliaqat/anaconda3/lib/python3.6/site-packages/flask/app.py\", line 1612, in full_dispatch_request\n",
      "    rv = self.dispatch_request()\n",
      "  File \"/home/abdulliaqat/anaconda3/lib/python3.6/site-packages/flask/app.py\", line 1598, in dispatch_request\n",
      "    return self.view_functions[rule.endpoint](**req.view_args)\n",
      "  File \"/home/abdulliaqat/anaconda3/lib/python3.6/site-packages/dash/dash.py\", line 558, in dispatch\n",
      "    return self.callback_map[target_id]['callback'](*args)\n",
      "  File \"/home/abdulliaqat/anaconda3/lib/python3.6/site-packages/dash/dash.py\", line 515, in add_context\n",
      "    output_value = func(*args, **kwargs)\n",
      "  File \"<ipython-input-27-c839ba81d55e>\", line 23, in update_graph\n",
      "    x=result.speed,\n",
      "NameError: name 'result' is not defined\n",
      "127.0.0.1 - - [22/Jul/2018 00:02:21] \"POST /_dash-update-component HTTP/1.1\" 500 -\n",
      "[2018-07-22 00:02:22,918] ERROR in app: Exception on /_dash-update-component [POST]\n",
      "Traceback (most recent call last):\n",
      "  File \"/home/abdulliaqat/anaconda3/lib/python3.6/site-packages/flask/app.py\", line 1982, in wsgi_app\n",
      "    response = self.full_dispatch_request()\n",
      "  File \"/home/abdulliaqat/anaconda3/lib/python3.6/site-packages/flask/app.py\", line 1614, in full_dispatch_request\n",
      "    rv = self.handle_user_exception(e)\n",
      "  File \"/home/abdulliaqat/anaconda3/lib/python3.6/site-packages/flask/app.py\", line 1517, in handle_user_exception\n",
      "    reraise(exc_type, exc_value, tb)\n",
      "  File \"/home/abdulliaqat/anaconda3/lib/python3.6/site-packages/flask/_compat.py\", line 33, in reraise\n",
      "    raise value\n",
      "  File \"/home/abdulliaqat/anaconda3/lib/python3.6/site-packages/flask/app.py\", line 1612, in full_dispatch_request\n",
      "    rv = self.dispatch_request()\n",
      "  File \"/home/abdulliaqat/anaconda3/lib/python3.6/site-packages/flask/app.py\", line 1598, in dispatch_request\n",
      "    return self.view_functions[rule.endpoint](**req.view_args)\n",
      "  File \"/home/abdulliaqat/anaconda3/lib/python3.6/site-packages/dash/dash.py\", line 558, in dispatch\n",
      "    return self.callback_map[target_id]['callback'](*args)\n",
      "  File \"/home/abdulliaqat/anaconda3/lib/python3.6/site-packages/dash/dash.py\", line 515, in add_context\n",
      "    output_value = func(*args, **kwargs)\n",
      "  File \"<ipython-input-27-c839ba81d55e>\", line 23, in update_graph\n",
      "    x=result.speed,\n",
      "NameError: name 'result' is not defined\n",
      "127.0.0.1 - - [22/Jul/2018 00:02:22] \"POST /_dash-update-component HTTP/1.1\" 500 -\n",
      "[2018-07-22 00:02:23,951] ERROR in app: Exception on /_dash-update-component [POST]\n",
      "Traceback (most recent call last):\n",
      "  File \"/home/abdulliaqat/anaconda3/lib/python3.6/site-packages/flask/app.py\", line 1982, in wsgi_app\n",
      "    response = self.full_dispatch_request()\n",
      "  File \"/home/abdulliaqat/anaconda3/lib/python3.6/site-packages/flask/app.py\", line 1614, in full_dispatch_request\n",
      "    rv = self.handle_user_exception(e)\n",
      "  File \"/home/abdulliaqat/anaconda3/lib/python3.6/site-packages/flask/app.py\", line 1517, in handle_user_exception\n",
      "    reraise(exc_type, exc_value, tb)\n",
      "  File \"/home/abdulliaqat/anaconda3/lib/python3.6/site-packages/flask/_compat.py\", line 33, in reraise\n",
      "    raise value\n",
      "  File \"/home/abdulliaqat/anaconda3/lib/python3.6/site-packages/flask/app.py\", line 1612, in full_dispatch_request\n",
      "    rv = self.dispatch_request()\n",
      "  File \"/home/abdulliaqat/anaconda3/lib/python3.6/site-packages/flask/app.py\", line 1598, in dispatch_request\n",
      "    return self.view_functions[rule.endpoint](**req.view_args)\n",
      "  File \"/home/abdulliaqat/anaconda3/lib/python3.6/site-packages/dash/dash.py\", line 558, in dispatch\n",
      "    return self.callback_map[target_id]['callback'](*args)\n",
      "  File \"/home/abdulliaqat/anaconda3/lib/python3.6/site-packages/dash/dash.py\", line 515, in add_context\n",
      "    output_value = func(*args, **kwargs)\n",
      "  File \"<ipython-input-27-c839ba81d55e>\", line 23, in update_graph\n",
      "    x=result.speed,\n",
      "NameError: name 'result' is not defined\n",
      "127.0.0.1 - - [22/Jul/2018 00:02:23] \"POST /_dash-update-component HTTP/1.1\" 500 -\n",
      "[2018-07-22 00:02:24,956] ERROR in app: Exception on /_dash-update-component [POST]\n",
      "Traceback (most recent call last):\n",
      "  File \"/home/abdulliaqat/anaconda3/lib/python3.6/site-packages/flask/app.py\", line 1982, in wsgi_app\n",
      "    response = self.full_dispatch_request()\n",
      "  File \"/home/abdulliaqat/anaconda3/lib/python3.6/site-packages/flask/app.py\", line 1614, in full_dispatch_request\n",
      "    rv = self.handle_user_exception(e)\n",
      "  File \"/home/abdulliaqat/anaconda3/lib/python3.6/site-packages/flask/app.py\", line 1517, in handle_user_exception\n",
      "    reraise(exc_type, exc_value, tb)\n",
      "  File \"/home/abdulliaqat/anaconda3/lib/python3.6/site-packages/flask/_compat.py\", line 33, in reraise\n",
      "    raise value\n",
      "  File \"/home/abdulliaqat/anaconda3/lib/python3.6/site-packages/flask/app.py\", line 1612, in full_dispatch_request\n",
      "    rv = self.dispatch_request()\n",
      "  File \"/home/abdulliaqat/anaconda3/lib/python3.6/site-packages/flask/app.py\", line 1598, in dispatch_request\n",
      "    return self.view_functions[rule.endpoint](**req.view_args)\n",
      "  File \"/home/abdulliaqat/anaconda3/lib/python3.6/site-packages/dash/dash.py\", line 558, in dispatch\n",
      "    return self.callback_map[target_id]['callback'](*args)\n",
      "  File \"/home/abdulliaqat/anaconda3/lib/python3.6/site-packages/dash/dash.py\", line 515, in add_context\n",
      "    output_value = func(*args, **kwargs)\n",
      "  File \"<ipython-input-27-c839ba81d55e>\", line 23, in update_graph\n",
      "    x=result.speed,\n",
      "NameError: name 'result' is not defined\n",
      "127.0.0.1 - - [22/Jul/2018 00:02:24] \"POST /_dash-update-component HTTP/1.1\" 500 -\n",
      "[2018-07-22 00:02:25,939] ERROR in app: Exception on /_dash-update-component [POST]\n",
      "Traceback (most recent call last):\n",
      "  File \"/home/abdulliaqat/anaconda3/lib/python3.6/site-packages/flask/app.py\", line 1982, in wsgi_app\n",
      "    response = self.full_dispatch_request()\n",
      "  File \"/home/abdulliaqat/anaconda3/lib/python3.6/site-packages/flask/app.py\", line 1614, in full_dispatch_request\n",
      "    rv = self.handle_user_exception(e)\n",
      "  File \"/home/abdulliaqat/anaconda3/lib/python3.6/site-packages/flask/app.py\", line 1517, in handle_user_exception\n",
      "    reraise(exc_type, exc_value, tb)\n",
      "  File \"/home/abdulliaqat/anaconda3/lib/python3.6/site-packages/flask/_compat.py\", line 33, in reraise\n",
      "    raise value\n",
      "  File \"/home/abdulliaqat/anaconda3/lib/python3.6/site-packages/flask/app.py\", line 1612, in full_dispatch_request\n",
      "    rv = self.dispatch_request()\n",
      "  File \"/home/abdulliaqat/anaconda3/lib/python3.6/site-packages/flask/app.py\", line 1598, in dispatch_request\n",
      "    return self.view_functions[rule.endpoint](**req.view_args)\n",
      "  File \"/home/abdulliaqat/anaconda3/lib/python3.6/site-packages/dash/dash.py\", line 558, in dispatch\n",
      "    return self.callback_map[target_id]['callback'](*args)\n",
      "  File \"/home/abdulliaqat/anaconda3/lib/python3.6/site-packages/dash/dash.py\", line 515, in add_context\n",
      "    output_value = func(*args, **kwargs)\n",
      "  File \"<ipython-input-27-c839ba81d55e>\", line 23, in update_graph\n",
      "    x=result.speed,\n",
      "NameError: name 'result' is not defined\n",
      "127.0.0.1 - - [22/Jul/2018 00:02:25] \"POST /_dash-update-component HTTP/1.1\" 500 -\n",
      "[2018-07-22 00:02:26,937] ERROR in app: Exception on /_dash-update-component [POST]\n",
      "Traceback (most recent call last):\n",
      "  File \"/home/abdulliaqat/anaconda3/lib/python3.6/site-packages/flask/app.py\", line 1982, in wsgi_app\n",
      "    response = self.full_dispatch_request()\n",
      "  File \"/home/abdulliaqat/anaconda3/lib/python3.6/site-packages/flask/app.py\", line 1614, in full_dispatch_request\n",
      "    rv = self.handle_user_exception(e)\n",
      "  File \"/home/abdulliaqat/anaconda3/lib/python3.6/site-packages/flask/app.py\", line 1517, in handle_user_exception\n",
      "    reraise(exc_type, exc_value, tb)\n",
      "  File \"/home/abdulliaqat/anaconda3/lib/python3.6/site-packages/flask/_compat.py\", line 33, in reraise\n",
      "    raise value\n",
      "  File \"/home/abdulliaqat/anaconda3/lib/python3.6/site-packages/flask/app.py\", line 1612, in full_dispatch_request\n",
      "    rv = self.dispatch_request()\n",
      "  File \"/home/abdulliaqat/anaconda3/lib/python3.6/site-packages/flask/app.py\", line 1598, in dispatch_request\n",
      "    return self.view_functions[rule.endpoint](**req.view_args)\n",
      "  File \"/home/abdulliaqat/anaconda3/lib/python3.6/site-packages/dash/dash.py\", line 558, in dispatch\n",
      "    return self.callback_map[target_id]['callback'](*args)\n",
      "  File \"/home/abdulliaqat/anaconda3/lib/python3.6/site-packages/dash/dash.py\", line 515, in add_context\n",
      "    output_value = func(*args, **kwargs)\n",
      "  File \"<ipython-input-27-c839ba81d55e>\", line 23, in update_graph\n",
      "    x=result.speed,\n",
      "NameError: name 'result' is not defined\n",
      "127.0.0.1 - - [22/Jul/2018 00:02:26] \"POST /_dash-update-component HTTP/1.1\" 500 -\n",
      "[2018-07-22 00:02:27,939] ERROR in app: Exception on /_dash-update-component [POST]\n",
      "Traceback (most recent call last):\n",
      "  File \"/home/abdulliaqat/anaconda3/lib/python3.6/site-packages/flask/app.py\", line 1982, in wsgi_app\n",
      "    response = self.full_dispatch_request()\n",
      "  File \"/home/abdulliaqat/anaconda3/lib/python3.6/site-packages/flask/app.py\", line 1614, in full_dispatch_request\n",
      "    rv = self.handle_user_exception(e)\n",
      "  File \"/home/abdulliaqat/anaconda3/lib/python3.6/site-packages/flask/app.py\", line 1517, in handle_user_exception\n",
      "    reraise(exc_type, exc_value, tb)\n",
      "  File \"/home/abdulliaqat/anaconda3/lib/python3.6/site-packages/flask/_compat.py\", line 33, in reraise\n",
      "    raise value\n",
      "  File \"/home/abdulliaqat/anaconda3/lib/python3.6/site-packages/flask/app.py\", line 1612, in full_dispatch_request\n",
      "    rv = self.dispatch_request()\n",
      "  File \"/home/abdulliaqat/anaconda3/lib/python3.6/site-packages/flask/app.py\", line 1598, in dispatch_request\n",
      "    return self.view_functions[rule.endpoint](**req.view_args)\n",
      "  File \"/home/abdulliaqat/anaconda3/lib/python3.6/site-packages/dash/dash.py\", line 558, in dispatch\n",
      "    return self.callback_map[target_id]['callback'](*args)\n",
      "  File \"/home/abdulliaqat/anaconda3/lib/python3.6/site-packages/dash/dash.py\", line 515, in add_context\n",
      "    output_value = func(*args, **kwargs)\n",
      "  File \"<ipython-input-27-c839ba81d55e>\", line 23, in update_graph\n",
      "    x=result.speed,\n",
      "NameError: name 'result' is not defined\n",
      "127.0.0.1 - - [22/Jul/2018 00:02:27] \"POST /_dash-update-component HTTP/1.1\" 500 -\n",
      "[2018-07-22 00:02:28,918] ERROR in app: Exception on /_dash-update-component [POST]\n",
      "Traceback (most recent call last):\n",
      "  File \"/home/abdulliaqat/anaconda3/lib/python3.6/site-packages/flask/app.py\", line 1982, in wsgi_app\n",
      "    response = self.full_dispatch_request()\n",
      "  File \"/home/abdulliaqat/anaconda3/lib/python3.6/site-packages/flask/app.py\", line 1614, in full_dispatch_request\n",
      "    rv = self.handle_user_exception(e)\n",
      "  File \"/home/abdulliaqat/anaconda3/lib/python3.6/site-packages/flask/app.py\", line 1517, in handle_user_exception\n",
      "    reraise(exc_type, exc_value, tb)\n",
      "  File \"/home/abdulliaqat/anaconda3/lib/python3.6/site-packages/flask/_compat.py\", line 33, in reraise\n",
      "    raise value\n",
      "  File \"/home/abdulliaqat/anaconda3/lib/python3.6/site-packages/flask/app.py\", line 1612, in full_dispatch_request\n",
      "    rv = self.dispatch_request()\n",
      "  File \"/home/abdulliaqat/anaconda3/lib/python3.6/site-packages/flask/app.py\", line 1598, in dispatch_request\n",
      "    return self.view_functions[rule.endpoint](**req.view_args)\n",
      "  File \"/home/abdulliaqat/anaconda3/lib/python3.6/site-packages/dash/dash.py\", line 558, in dispatch\n",
      "    return self.callback_map[target_id]['callback'](*args)\n",
      "  File \"/home/abdulliaqat/anaconda3/lib/python3.6/site-packages/dash/dash.py\", line 515, in add_context\n",
      "    output_value = func(*args, **kwargs)\n",
      "  File \"<ipython-input-27-c839ba81d55e>\", line 23, in update_graph\n",
      "    x=result.speed,\n",
      "NameError: name 'result' is not defined\n",
      "127.0.0.1 - - [22/Jul/2018 00:02:28] \"POST /_dash-update-component HTTP/1.1\" 500 -\n",
      "[2018-07-22 00:02:29,916] ERROR in app: Exception on /_dash-update-component [POST]\n",
      "Traceback (most recent call last):\n",
      "  File \"/home/abdulliaqat/anaconda3/lib/python3.6/site-packages/flask/app.py\", line 1982, in wsgi_app\n",
      "    response = self.full_dispatch_request()\n",
      "  File \"/home/abdulliaqat/anaconda3/lib/python3.6/site-packages/flask/app.py\", line 1614, in full_dispatch_request\n",
      "    rv = self.handle_user_exception(e)\n",
      "  File \"/home/abdulliaqat/anaconda3/lib/python3.6/site-packages/flask/app.py\", line 1517, in handle_user_exception\n",
      "    reraise(exc_type, exc_value, tb)\n",
      "  File \"/home/abdulliaqat/anaconda3/lib/python3.6/site-packages/flask/_compat.py\", line 33, in reraise\n",
      "    raise value\n",
      "  File \"/home/abdulliaqat/anaconda3/lib/python3.6/site-packages/flask/app.py\", line 1612, in full_dispatch_request\n",
      "    rv = self.dispatch_request()\n",
      "  File \"/home/abdulliaqat/anaconda3/lib/python3.6/site-packages/flask/app.py\", line 1598, in dispatch_request\n",
      "    return self.view_functions[rule.endpoint](**req.view_args)\n",
      "  File \"/home/abdulliaqat/anaconda3/lib/python3.6/site-packages/dash/dash.py\", line 558, in dispatch\n",
      "    return self.callback_map[target_id]['callback'](*args)\n",
      "  File \"/home/abdulliaqat/anaconda3/lib/python3.6/site-packages/dash/dash.py\", line 515, in add_context\n",
      "    output_value = func(*args, **kwargs)\n",
      "  File \"<ipython-input-27-c839ba81d55e>\", line 23, in update_graph\n",
      "    x=result.speed,\n",
      "NameError: name 'result' is not defined\n",
      "127.0.0.1 - - [22/Jul/2018 00:02:29] \"POST /_dash-update-component HTTP/1.1\" 500 -\n",
      "[2018-07-22 00:02:30,602] ERROR in app: Exception on /_dash-update-component [POST]\n",
      "Traceback (most recent call last):\n",
      "  File \"/home/abdulliaqat/anaconda3/lib/python3.6/site-packages/flask/app.py\", line 1982, in wsgi_app\n",
      "    response = self.full_dispatch_request()\n",
      "  File \"/home/abdulliaqat/anaconda3/lib/python3.6/site-packages/flask/app.py\", line 1614, in full_dispatch_request\n",
      "    rv = self.handle_user_exception(e)\n",
      "  File \"/home/abdulliaqat/anaconda3/lib/python3.6/site-packages/flask/app.py\", line 1517, in handle_user_exception\n",
      "    reraise(exc_type, exc_value, tb)\n",
      "  File \"/home/abdulliaqat/anaconda3/lib/python3.6/site-packages/flask/_compat.py\", line 33, in reraise\n",
      "    raise value\n",
      "  File \"/home/abdulliaqat/anaconda3/lib/python3.6/site-packages/flask/app.py\", line 1612, in full_dispatch_request\n",
      "    rv = self.dispatch_request()\n",
      "  File \"/home/abdulliaqat/anaconda3/lib/python3.6/site-packages/flask/app.py\", line 1598, in dispatch_request\n",
      "    return self.view_functions[rule.endpoint](**req.view_args)\n",
      "  File \"/home/abdulliaqat/anaconda3/lib/python3.6/site-packages/dash/dash.py\", line 558, in dispatch\n",
      "    return self.callback_map[target_id]['callback'](*args)\n",
      "  File \"/home/abdulliaqat/anaconda3/lib/python3.6/site-packages/dash/dash.py\", line 515, in add_context\n",
      "    output_value = func(*args, **kwargs)\n",
      "  File \"<ipython-input-27-c839ba81d55e>\", line 23, in update_graph\n",
      "    x=result.speed,\n",
      "NameError: name 'result' is not defined\n",
      "127.0.0.1 - - [22/Jul/2018 00:02:30] \"POST /_dash-update-component HTTP/1.1\" 500 -\n"
     ]
    }
   ],
   "source": [
    "if __name__ == '__main__':\n",
    "    app.run_server(host='0.0.0.0')\n"
   ]
  },
  {
   "cell_type": "code",
   "execution_count": 29,
   "metadata": {},
   "outputs": [],
   "source": [
    "data = pd.read_csv('data/data.csv')"
   ]
  },
  {
   "cell_type": "code",
   "execution_count": 33,
   "metadata": {},
   "outputs": [],
   "source": [
    "data.groupby(['lat','long']).get_group((40.665790,-73.757060)).to_csv('data/group_40.665790_73.757060.csv')"
   ]
  },
  {
   "cell_type": "code",
   "execution_count": 34,
   "metadata": {},
   "outputs": [],
   "source": [
    "from time import time"
   ]
  },
  {
   "cell_type": "code",
   "execution_count": 118,
   "metadata": {},
   "outputs": [
    {
     "data": {
      "text/plain": [
       "1532214844"
      ]
     },
     "execution_count": 118,
     "metadata": {},
     "output_type": "execute_result"
    }
   ],
   "source": [
    "int(time())+2"
   ]
  },
  {
   "cell_type": "code",
   "execution_count": null,
   "metadata": {},
   "outputs": [],
   "source": []
  },
  {
   "cell_type": "code",
   "execution_count": null,
   "metadata": {},
   "outputs": [],
   "source": []
  }
 ],
 "metadata": {
  "kernelspec": {
   "display_name": "Python 3",
   "language": "python",
   "name": "python3"
  },
  "language_info": {
   "codemirror_mode": {
    "name": "ipython",
    "version": 3
   },
   "file_extension": ".py",
   "mimetype": "text/x-python",
   "name": "python",
   "nbconvert_exporter": "python",
   "pygments_lexer": "ipython3",
   "version": "3.6.1"
  }
 },
 "nbformat": 4,
 "nbformat_minor": 2
}
